<?xml version="1.0" ?>

 


<robot name="robot">
<!--MX64trntbl + MX106:  ? + 0.153 -->
<!-- singleaxismount + 2.5girder + singleaxismount + base + MX106: 0.007370876 + 0.0226796 + 0.007370876 + ? + 0.153 -->
<!-- frame106 + singleaxismount + adjustgirder + singleaxismount + base + MX28: 0.0907185 + 0.00737088 + 0.110563 + 0.00737088 + ? + 0.077 -->
<!-- frame28 + singleaxismount + 5girder + singleaxismount + base + MX28: 0.0907185 + 0.00737088 + 0.0368544 + 0.00737088 + ? + 0.077 -->
<!-- frame28 + singleaxismount + 2.5girder + singleaxismount + tip: 0.0907185 + 0.00737088 + 0.0226796 + 0.00737088 + ? -->


<material name="omni/Blue">
<color rgba="0 0 0.8 1"/>
</material>

<material name="omni/Red">
<color rgba="1 0 0 1"/>
</material>

<material name="omni/Green">
<color rgba="0 1 0 1"/>
</material>

<material name="omni/Yellow">
<color rgba="1 1 0 1"/>
</material>

<material name="omni/LightGrey">
<color rgba="0.6 0.6 0.6 1"/>
</material>

<material name="omni/DarkGrey">
<color rgba="0.4 0.4 0.4 1"/>
</material> 

<material name="omni/Black">
<color rgba="0 0 0 1"/>
</material>




<link name="base">
	<visual>
	<origin rpy="0 0 0" xyz="0 0 0"/>
	<geometry>
	<box size="0.2 0.2 0.2"/>
	</geometry>	
	<material name="omni/Blue"/>
	</visual>
</link>


<link name="arm_link_1">
	<visual>
		<origin rpy="0 0 0" xyz="0 0 0.075"/>
		<geometry>
			<box size="0.15 0.15 0.15"/>
		</geometry>
		<material name="omni/Red"/>
	</visual>
</link>


<joint name="arm_joint_1" type="revolute">
	<parent link="base"/>
	<child link="arm_link_1"/>
	<limit effort="30.0" lower="-1.57079632679" upper="1.57079632679" velocity="5.0"/>
	<origin rpy="0 0 0" xyz="0 0 0.1"/>
	<axis xyz="0 0 1"/>
</joint>



<link name="arm_link_2">
	<visual>
		<origin rpy="0 0 0" xyz="0 0 0.111"/>
		<geometry>
			<box size="0.025 0.025 0.222"/>
		</geometry>
		<material name="omni/Green"/>
	</visual>
</link>


<joint name="arm_joint_2" type="revolute">
	<parent link="arm_link_1"/>
	<child link="arm_link_2"/>
	<limit effort="30.0" lower="-1.57079632679" upper="1.57079632679" velocity="5.0"/>
	<origin rpy="0 0 0" xyz="0 0 0.15"/>
	<axis xyz="1 0 0"/>
</joint>


<link name="arm_link_3">
	<visual>
		<origin rpy="0 0 0" xyz="0 0 0.111"/>
		<geometry>
			<box size="0.025 0.025 0.222"/>
		</geometry>
		<material name="omni/Yellow"/>
	</visual>
</link>


<joint name="arm_joint_3" type="revolute">
	<parent link="arm_link_2"/>
	<child link="arm_link_3"/>
	<limit effort="30.0" lower="-1.57079632679" upper="1.57079632679" velocity="5.0"/>
	<origin rpy="0 0 0" xyz="0 0 0.216"/>
	<axis xyz="1 0 0"/>
</joint>


<link name="arm_link_4">
	<visual>
		<origin rpy="0 0 0" xyz="0 0 0.071"/>
		<geometry>
			<box size="0.025 0.025 0.135"/>
		</geometry>
		<material name="omni/Red"/>
	</visual>
</link>


<joint name="arm_joint_4" type="revolute">
	<parent link="arm_link_3"/>
	<child link="arm_link_4"/>
	<limit effort="30.0" lower="-1.57079632679" upper="1.57079632679" velocity="5.0"/>
	<origin rpy="0 0 0" xyz="0 0 0.217"/>
	<axis xyz="1 0 0"/>
</joint>


<link name="arm_link_5">
	<visual>
		<origin rpy="0 0 0" xyz="0 0 0.021"/>
		<geometry>
			<box size="0.05 0.1 0.05"/>
		</geometry>
		<material name="omni/Black"/>
	</visual>
</link>


<joint name="arm_joint_5" type="revolute">
	<parent link="arm_link_4"/>
	<child link="arm_link_5"/>
	<limit effort="30.0" lower="-1.57079632679" upper="1.57079632679" velocity="5.0"/>
	<origin rpy="0 0 0" xyz="0 0 0.137"/>
	<axis xyz="0 0 1"/>
</joint>


</robot>
